[2023-05-23 21:04:18,075] {taskinstance.py:1159} INFO - Dependencies all met for <TaskInstance: data_ingestion_gcs_dag.bigquery_external_table_task manual__2023-05-23T21:04:10.480678+00:00 [queued]>
[2023-05-23 21:04:18,088] {taskinstance.py:1159} INFO - Dependencies all met for <TaskInstance: data_ingestion_gcs_dag.bigquery_external_table_task manual__2023-05-23T21:04:10.480678+00:00 [queued]>
[2023-05-23 21:04:18,089] {taskinstance.py:1356} INFO - 
--------------------------------------------------------------------------------
[2023-05-23 21:04:18,091] {taskinstance.py:1357} INFO - Starting attempt 1 of 2
[2023-05-23 21:04:18,092] {taskinstance.py:1358} INFO - 
--------------------------------------------------------------------------------
[2023-05-23 21:04:18,111] {taskinstance.py:1377} INFO - Executing <Task(BigQueryCreateExternalTableOperator): bigquery_external_table_task> on 2023-05-23 21:04:10.480678+00:00
[2023-05-23 21:04:18,117] {standard_task_runner.py:52} INFO - Started process 216 to run task
[2023-05-23 21:04:18,121] {standard_task_runner.py:79} INFO - Running: ['***', 'tasks', 'run', 'data_ingestion_gcs_dag', 'bigquery_external_table_task', 'manual__2023-05-23T21:04:10.480678+00:00', '--job-id', '43', '--raw', '--subdir', 'DAGS_FOLDER/data_ingestion_gcs.py', '--cfg-path', '/tmp/tmp2v3n4c12', '--error-file', '/tmp/tmp_fxc0pt4']
[2023-05-23 21:04:18,123] {standard_task_runner.py:80} INFO - Job 43: Subtask bigquery_external_table_task
[2023-05-23 21:04:18,184] {task_command.py:370} INFO - Running <TaskInstance: data_ingestion_gcs_dag.bigquery_external_table_task manual__2023-05-23T21:04:10.480678+00:00 [running]> on host ca6ba07bb7b3
[2023-05-23 21:04:18,264] {taskinstance.py:1571} INFO - Exporting the following env vars:
AIRFLOW_CTX_DAG_OWNER=***
AIRFLOW_CTX_DAG_ID=data_ingestion_gcs_dag
AIRFLOW_CTX_TASK_ID=bigquery_external_table_task
AIRFLOW_CTX_EXECUTION_DATE=2023-05-23T21:04:10.480678+00:00
AIRFLOW_CTX_TRY_NUMBER=1
AIRFLOW_CTX_DAG_RUN_ID=manual__2023-05-23T21:04:10.480678+00:00
[2023-05-23 21:04:18,267] {crypto.py:82} WARNING - empty cryptography key - values will not be stored encrypted.
[2023-05-23 21:04:18,268] {base.py:68} INFO - Using connection ID 'google_cloud_default' for task execution.
[2023-05-23 21:04:18,804] {taskinstance.py:1889} ERROR - Task failed with exception
Traceback (most recent call last):
  File "/home/airflow/.local/lib/python3.7/site-packages/airflow/providers/google/cloud/operators/bigquery.py", line 1108, in execute
    table_resource=self.table_resource,
  File "/home/airflow/.local/lib/python3.7/site-packages/airflow/providers/google/common/hooks/base_google.py", line 439, in inner_wrapper
    return func(self, *args, **kwargs)
  File "/home/airflow/.local/lib/python3.7/site-packages/airflow/providers/google/cloud/hooks/bigquery.py", line 400, in create_empty_table
    table=table, exists_ok=exists_ok, retry=retry
  File "/home/airflow/.local/lib/python3.7/site-packages/google/cloud/bigquery/client.py", line 755, in create_table
    timeout=timeout,
  File "/home/airflow/.local/lib/python3.7/site-packages/google/cloud/bigquery/client.py", line 782, in _call_api
    return call()
  File "/home/airflow/.local/lib/python3.7/site-packages/google/api_core/retry.py", line 288, in retry_wrapped_func
    on_error=on_error,
  File "/home/airflow/.local/lib/python3.7/site-packages/google/api_core/retry.py", line 190, in retry_target
    return target()
  File "/home/airflow/.local/lib/python3.7/site-packages/google/cloud/_http/__init__.py", line 494, in api_request
    raise exceptions.from_http_response(response)
google.api_core.exceptions.NotFound: 404 POST https://bigquery.googleapis.com/bigquery/v2/projects/twitter-etl-385111/datasets/trips_data_all/tables?prettyPrint=false: Not found: Dataset twitter-etl-385111:trips_data_all
[2023-05-23 21:04:18,818] {taskinstance.py:1400} INFO - Marking task as UP_FOR_RETRY. dag_id=data_ingestion_gcs_dag, task_id=bigquery_external_table_task, execution_date=20230523T210410, start_date=20230523T210418, end_date=20230523T210418
[2023-05-23 21:04:18,829] {standard_task_runner.py:97} ERROR - Failed to execute job 43 for task bigquery_external_table_task (404 POST https://bigquery.googleapis.com/bigquery/v2/projects/twitter-etl-385111/datasets/trips_data_all/tables?prettyPrint=false: Not found: Dataset twitter-etl-385111:trips_data_all; 216)
[2023-05-23 21:04:18,859] {local_task_job.py:156} INFO - Task exited with return code 1
[2023-05-23 21:04:18,892] {local_task_job.py:273} INFO - 0 downstream tasks scheduled from follow-on schedule check
