[2023-05-22 13:54:54,396] {taskinstance.py:1159} INFO - Dependencies all met for <TaskInstance: data_ingestion_gcs_dag.local_to_gcs_task manual__2023-05-22T13:49:45.167285+00:00 [queued]>
[2023-05-22 13:54:54,407] {taskinstance.py:1159} INFO - Dependencies all met for <TaskInstance: data_ingestion_gcs_dag.local_to_gcs_task manual__2023-05-22T13:49:45.167285+00:00 [queued]>
[2023-05-22 13:54:54,408] {taskinstance.py:1356} INFO - 
--------------------------------------------------------------------------------
[2023-05-22 13:54:54,409] {taskinstance.py:1357} INFO - Starting attempt 2 of 2
[2023-05-22 13:54:54,410] {taskinstance.py:1358} INFO - 
--------------------------------------------------------------------------------
[2023-05-22 13:54:54,422] {taskinstance.py:1377} INFO - Executing <Task(PythonOperator): local_to_gcs_task> on 2023-05-22 13:49:45.167285+00:00
[2023-05-22 13:54:54,427] {standard_task_runner.py:52} INFO - Started process 1862 to run task
[2023-05-22 13:54:54,430] {standard_task_runner.py:79} INFO - Running: ['***', 'tasks', 'run', 'data_ingestion_gcs_dag', 'local_to_gcs_task', 'manual__2023-05-22T13:49:45.167285+00:00', '--job-id', '10', '--raw', '--subdir', 'DAGS_FOLDER/data_ingestion_gcs.py', '--cfg-path', '/tmp/tmpdr41wgux', '--error-file', '/tmp/tmpkeg4md9l']
[2023-05-22 13:54:54,432] {standard_task_runner.py:80} INFO - Job 10: Subtask local_to_gcs_task
[2023-05-22 13:54:54,486] {task_command.py:370} INFO - Running <TaskInstance: data_ingestion_gcs_dag.local_to_gcs_task manual__2023-05-22T13:49:45.167285+00:00 [running]> on host 5436e4fb5b09
[2023-05-22 13:54:54,553] {taskinstance.py:1571} INFO - Exporting the following env vars:
AIRFLOW_CTX_DAG_OWNER=***
AIRFLOW_CTX_DAG_ID=data_ingestion_gcs_dag
AIRFLOW_CTX_TASK_ID=local_to_gcs_task
AIRFLOW_CTX_EXECUTION_DATE=2023-05-22T13:49:45.167285+00:00
AIRFLOW_CTX_TRY_NUMBER=2
AIRFLOW_CTX_DAG_RUN_ID=manual__2023-05-22T13:49:45.167285+00:00
[2023-05-22 13:54:54,661] {taskinstance.py:1889} ERROR - Task failed with exception
Traceback (most recent call last):
  File "/home/airflow/.local/lib/python3.7/site-packages/airflow/operators/python.py", line 171, in execute
    return_value = self.execute_callable()
  File "/home/airflow/.local/lib/python3.7/site-packages/airflow/operators/python.py", line 189, in execute_callable
    return self.python_callable(*self.op_args, **self.op_kwargs)
  File "/Users/eugene/Personal_Projects/Data_Project/app/airflow/dags/data_ingestion_gcs.py", line 41, in upload_to_gcs
    blob.upload_from_filename(local_file)
  File "/home/airflow/.local/lib/python3.7/site-packages/google/cloud/storage/blob.py", line 2735, in upload_from_filename
    retry=retry,
  File "/home/airflow/.local/lib/python3.7/site-packages/google/cloud/storage/blob.py", line 2594, in upload_from_file
    retry=retry,
  File "/home/airflow/.local/lib/python3.7/site-packages/google/cloud/storage/blob.py", line 2412, in _do_upload
    retry=retry,
  File "/home/airflow/.local/lib/python3.7/site-packages/google/cloud/storage/blob.py", line 2237, in _do_resumable_upload
    retry=retry,
  File "/home/airflow/.local/lib/python3.7/site-packages/google/cloud/storage/blob.py", line 2112, in _initiate_resumable_upload
    timeout=timeout,
  File "/home/airflow/.local/lib/python3.7/site-packages/google/resumable_media/requests/upload.py", line 421, in initiate
    retriable_request, self._get_status_code, self._retry_strategy
  File "/home/airflow/.local/lib/python3.7/site-packages/google/resumable_media/requests/_request_helpers.py", line 148, in wait_and_retry
    response = func()
  File "/home/airflow/.local/lib/python3.7/site-packages/google/resumable_media/requests/upload.py", line 413, in retriable_request
    method, url, data=payload, headers=headers, timeout=timeout
  File "/home/airflow/.local/lib/python3.7/site-packages/google/auth/transport/requests.py", line 486, in request
    self.credentials.before_request(auth_request, method, url, request_headers)
  File "/home/airflow/.local/lib/python3.7/site-packages/google/auth/credentials.py", line 133, in before_request
    self.refresh(request)
  File "/home/airflow/.local/lib/python3.7/site-packages/google/oauth2/service_account.py", line 411, in refresh
    request, self._token_uri, assertion
  File "/home/airflow/.local/lib/python3.7/site-packages/google/oauth2/_client.py", line 193, in jwt_grant
    response_data = _token_endpoint_request(request, token_uri, body)
  File "/home/airflow/.local/lib/python3.7/site-packages/google/oauth2/_client.py", line 165, in _token_endpoint_request
    _handle_error_response(response_data)
  File "/home/airflow/.local/lib/python3.7/site-packages/google/oauth2/_client.py", line 60, in _handle_error_response
    raise exceptions.RefreshError(error_details, response_data)
google.auth.exceptions.RefreshError: ('invalid_grant: Invalid grant: account not found', {'error': 'invalid_grant', 'error_description': 'Invalid grant: account not found'})
[2023-05-22 13:54:54,675] {taskinstance.py:1400} INFO - Marking task as FAILED. dag_id=data_ingestion_gcs_dag, task_id=local_to_gcs_task, execution_date=20230522T134945, start_date=20230522T135454, end_date=20230522T135454
[2023-05-22 13:54:54,686] {standard_task_runner.py:97} ERROR - Failed to execute job 10 for task local_to_gcs_task (('invalid_grant: Invalid grant: account not found', {'error': 'invalid_grant', 'error_description': 'Invalid grant: account not found'}); 1862)
[2023-05-22 13:54:54,724] {local_task_job.py:156} INFO - Task exited with return code 1
[2023-05-22 13:54:54,762] {local_task_job.py:273} INFO - 0 downstream tasks scheduled from follow-on schedule check
