[2023-05-22 13:00:22,459] {taskinstance.py:1159} INFO - Dependencies all met for <TaskInstance: data_ingestion_gcs_dag.local_to_gcs_task scheduled__2023-05-21T00:00:00+00:00 [queued]>
[2023-05-22 13:00:22,470] {taskinstance.py:1159} INFO - Dependencies all met for <TaskInstance: data_ingestion_gcs_dag.local_to_gcs_task scheduled__2023-05-21T00:00:00+00:00 [queued]>
[2023-05-22 13:00:22,471] {taskinstance.py:1356} INFO - 
--------------------------------------------------------------------------------
[2023-05-22 13:00:22,472] {taskinstance.py:1357} INFO - Starting attempt 2 of 2
[2023-05-22 13:00:22,472] {taskinstance.py:1358} INFO - 
--------------------------------------------------------------------------------
[2023-05-22 13:00:22,484] {taskinstance.py:1377} INFO - Executing <Task(PythonOperator): local_to_gcs_task> on 2023-05-21 00:00:00+00:00
[2023-05-22 13:00:22,490] {standard_task_runner.py:52} INFO - Started process 436 to run task
[2023-05-22 13:00:22,494] {standard_task_runner.py:79} INFO - Running: ['***', 'tasks', 'run', 'data_ingestion_gcs_dag', 'local_to_gcs_task', 'scheduled__2023-05-21T00:00:00+00:00', '--job-id', '4', '--raw', '--subdir', 'DAGS_FOLDER/data_ingestion_gcs.py', '--cfg-path', '/tmp/tmpq98wq5k5', '--error-file', '/tmp/tmpfz6gf3w7']
[2023-05-22 13:00:22,495] {standard_task_runner.py:80} INFO - Job 4: Subtask local_to_gcs_task
[2023-05-22 13:00:22,554] {task_command.py:370} INFO - Running <TaskInstance: data_ingestion_gcs_dag.local_to_gcs_task scheduled__2023-05-21T00:00:00+00:00 [running]> on host 5436e4fb5b09
[2023-05-22 13:00:22,643] {taskinstance.py:1571} INFO - Exporting the following env vars:
AIRFLOW_CTX_DAG_OWNER=***
AIRFLOW_CTX_DAG_ID=data_ingestion_gcs_dag
AIRFLOW_CTX_TASK_ID=local_to_gcs_task
AIRFLOW_CTX_EXECUTION_DATE=2023-05-21T00:00:00+00:00
AIRFLOW_CTX_TRY_NUMBER=2
AIRFLOW_CTX_DAG_RUN_ID=scheduled__2023-05-21T00:00:00+00:00
[2023-05-22 13:00:22,777] {taskinstance.py:1889} ERROR - Task failed with exception
Traceback (most recent call last):
  File "/home/airflow/.local/lib/python3.7/site-packages/airflow/operators/python.py", line 171, in execute
    return_value = self.execute_callable()
  File "/home/airflow/.local/lib/python3.7/site-packages/airflow/operators/python.py", line 189, in execute_callable
    return self.python_callable(*self.op_args, **self.op_kwargs)
  File "/Users/eugene/Personal_Projects/Data_Project/app/airflow/dags/data_ingestion_gcs.py", line 41, in upload_to_gcs
    blob.upload_from_filename(local_file)
  File "/home/airflow/.local/lib/python3.7/site-packages/google/cloud/storage/blob.py", line 2735, in upload_from_filename
    retry=retry,
  File "/home/airflow/.local/lib/python3.7/site-packages/google/cloud/storage/blob.py", line 2594, in upload_from_file
    retry=retry,
  File "/home/airflow/.local/lib/python3.7/site-packages/google/cloud/storage/blob.py", line 2412, in _do_upload
    retry=retry,
  File "/home/airflow/.local/lib/python3.7/site-packages/google/cloud/storage/blob.py", line 2237, in _do_resumable_upload
    retry=retry,
  File "/home/airflow/.local/lib/python3.7/site-packages/google/cloud/storage/blob.py", line 2112, in _initiate_resumable_upload
    timeout=timeout,
  File "/home/airflow/.local/lib/python3.7/site-packages/google/resumable_media/requests/upload.py", line 421, in initiate
    retriable_request, self._get_status_code, self._retry_strategy
  File "/home/airflow/.local/lib/python3.7/site-packages/google/resumable_media/requests/_request_helpers.py", line 148, in wait_and_retry
    response = func()
  File "/home/airflow/.local/lib/python3.7/site-packages/google/resumable_media/requests/upload.py", line 413, in retriable_request
    method, url, data=payload, headers=headers, timeout=timeout
  File "/home/airflow/.local/lib/python3.7/site-packages/google/auth/transport/requests.py", line 486, in request
    self.credentials.before_request(auth_request, method, url, request_headers)
  File "/home/airflow/.local/lib/python3.7/site-packages/google/auth/credentials.py", line 133, in before_request
    self.refresh(request)
  File "/home/airflow/.local/lib/python3.7/site-packages/google/oauth2/service_account.py", line 411, in refresh
    request, self._token_uri, assertion
  File "/home/airflow/.local/lib/python3.7/site-packages/google/oauth2/_client.py", line 193, in jwt_grant
    response_data = _token_endpoint_request(request, token_uri, body)
  File "/home/airflow/.local/lib/python3.7/site-packages/google/oauth2/_client.py", line 165, in _token_endpoint_request
    _handle_error_response(response_data)
  File "/home/airflow/.local/lib/python3.7/site-packages/google/oauth2/_client.py", line 60, in _handle_error_response
    raise exceptions.RefreshError(error_details, response_data)
google.auth.exceptions.RefreshError: ('invalid_grant: Invalid grant: account not found', {'error': 'invalid_grant', 'error_description': 'Invalid grant: account not found'})
[2023-05-22 13:00:22,796] {taskinstance.py:1400} INFO - Marking task as FAILED. dag_id=data_ingestion_gcs_dag, task_id=local_to_gcs_task, execution_date=20230521T000000, start_date=20230522T130022, end_date=20230522T130022
[2023-05-22 13:00:22,808] {standard_task_runner.py:97} ERROR - Failed to execute job 4 for task local_to_gcs_task (('invalid_grant: Invalid grant: account not found', {'error': 'invalid_grant', 'error_description': 'Invalid grant: account not found'}); 436)
[2023-05-22 13:00:22,828] {local_task_job.py:156} INFO - Task exited with return code 1
[2023-05-22 13:00:22,869] {local_task_job.py:273} INFO - 0 downstream tasks scheduled from follow-on schedule check
[2023-05-22 14:20:45,524] {taskinstance.py:1159} INFO - Dependencies all met for <TaskInstance: data_ingestion_gcs_dag.local_to_gcs_task scheduled__2023-05-21T00:00:00+00:00 [queued]>
[2023-05-22 14:20:45,534] {taskinstance.py:1159} INFO - Dependencies all met for <TaskInstance: data_ingestion_gcs_dag.local_to_gcs_task scheduled__2023-05-21T00:00:00+00:00 [queued]>
[2023-05-22 14:20:45,535] {taskinstance.py:1356} INFO - 
--------------------------------------------------------------------------------
[2023-05-22 14:20:45,536] {taskinstance.py:1357} INFO - Starting attempt 2 of 2
[2023-05-22 14:20:45,537] {taskinstance.py:1358} INFO - 
--------------------------------------------------------------------------------
[2023-05-22 14:20:45,549] {taskinstance.py:1377} INFO - Executing <Task(PythonOperator): local_to_gcs_task> on 2023-05-21 00:00:00+00:00
[2023-05-22 14:20:45,554] {standard_task_runner.py:52} INFO - Started process 415 to run task
[2023-05-22 14:20:45,557] {standard_task_runner.py:79} INFO - Running: ['***', 'tasks', 'run', 'data_ingestion_gcs_dag', 'local_to_gcs_task', 'scheduled__2023-05-21T00:00:00+00:00', '--job-id', '16', '--raw', '--subdir', 'DAGS_FOLDER/data_ingestion_gcs.py', '--cfg-path', '/tmp/tmpnj6w3is9', '--error-file', '/tmp/tmpzhbwwrf9']
[2023-05-22 14:20:45,559] {standard_task_runner.py:80} INFO - Job 16: Subtask local_to_gcs_task
[2023-05-22 14:20:45,613] {task_command.py:370} INFO - Running <TaskInstance: data_ingestion_gcs_dag.local_to_gcs_task scheduled__2023-05-21T00:00:00+00:00 [running]> on host bfd57a4116d5
[2023-05-22 14:20:45,681] {taskinstance.py:1571} INFO - Exporting the following env vars:
AIRFLOW_CTX_DAG_OWNER=***
AIRFLOW_CTX_DAG_ID=data_ingestion_gcs_dag
AIRFLOW_CTX_TASK_ID=local_to_gcs_task
AIRFLOW_CTX_EXECUTION_DATE=2023-05-21T00:00:00+00:00
AIRFLOW_CTX_TRY_NUMBER=2
AIRFLOW_CTX_DAG_RUN_ID=scheduled__2023-05-21T00:00:00+00:00
[2023-05-22 14:20:45,900] {taskinstance.py:1889} ERROR - Task failed with exception
Traceback (most recent call last):
  File "/home/airflow/.local/lib/python3.7/site-packages/google/cloud/storage/blob.py", line 2594, in upload_from_file
    retry=retry,
  File "/home/airflow/.local/lib/python3.7/site-packages/google/cloud/storage/blob.py", line 2412, in _do_upload
    retry=retry,
  File "/home/airflow/.local/lib/python3.7/site-packages/google/cloud/storage/blob.py", line 2237, in _do_resumable_upload
    retry=retry,
  File "/home/airflow/.local/lib/python3.7/site-packages/google/cloud/storage/blob.py", line 2112, in _initiate_resumable_upload
    timeout=timeout,
  File "/home/airflow/.local/lib/python3.7/site-packages/google/resumable_media/requests/upload.py", line 421, in initiate
    retriable_request, self._get_status_code, self._retry_strategy
  File "/home/airflow/.local/lib/python3.7/site-packages/google/resumable_media/requests/_request_helpers.py", line 148, in wait_and_retry
    response = func()
  File "/home/airflow/.local/lib/python3.7/site-packages/google/resumable_media/requests/upload.py", line 416, in retriable_request
    self._process_initiate_response(result)
  File "/home/airflow/.local/lib/python3.7/site-packages/google/resumable_media/_upload.py", line 513, in _process_initiate_response
    callback=self._make_invalid,
  File "/home/airflow/.local/lib/python3.7/site-packages/google/resumable_media/_helpers.py", line 110, in require_status_code
    *status_codes
google.resumable_media.common.InvalidResponse: ('Request failed with status code', 403, 'Expected one of', <HTTPStatus.OK: 200>, <HTTPStatus.CREATED: 201>)

During handling of the above exception, another exception occurred:

Traceback (most recent call last):
  File "/home/airflow/.local/lib/python3.7/site-packages/airflow/operators/python.py", line 171, in execute
    return_value = self.execute_callable()
  File "/home/airflow/.local/lib/python3.7/site-packages/airflow/operators/python.py", line 189, in execute_callable
    return self.python_callable(*self.op_args, **self.op_kwargs)
  File "/Users/eugene/Personal_Projects/Data_Project/app/airflow/dags/data_ingestion_gcs.py", line 41, in upload_to_gcs
    blob.upload_from_filename(local_file)
  File "/home/airflow/.local/lib/python3.7/site-packages/google/cloud/storage/blob.py", line 2735, in upload_from_filename
    retry=retry,
  File "/home/airflow/.local/lib/python3.7/site-packages/google/cloud/storage/blob.py", line 2598, in upload_from_file
    _raise_from_invalid_response(exc)
  File "/home/airflow/.local/lib/python3.7/site-packages/google/cloud/storage/blob.py", line 4470, in _raise_from_invalid_response
    raise exceptions.from_http_status(response.status_code, message, response=response)
google.api_core.exceptions.Forbidden: 403 POST https://storage.googleapis.com/upload/storage/v1/b/twitter-etl-bucket/o?uploadType=resumable: {
  "error": {
    "code": 403,
    "message": "690814178061-compute@developer.gserviceaccount.com does not have storage.objects.create access to the Google Cloud Storage object. Permission 'storage.objects.create' denied on resource (or it may not exist).",
    "errors": [
      {
        "message": "690814178061-compute@developer.gserviceaccount.com does not have storage.objects.create access to the Google Cloud Storage object. Permission 'storage.objects.create' denied on resource (or it may not exist).",
        "domain": "global",
        "reason": "forbidden"
      }
    ]
  }
}
: ('Request failed with status code', 403, 'Expected one of', <HTTPStatus.OK: 200>, <HTTPStatus.CREATED: 201>)
[2023-05-22 14:20:45,918] {taskinstance.py:1400} INFO - Marking task as FAILED. dag_id=data_ingestion_gcs_dag, task_id=local_to_gcs_task, execution_date=20230521T000000, start_date=20230522T142045, end_date=20230522T142045
[2023-05-22 14:20:45,931] {standard_task_runner.py:97} ERROR - Failed to execute job 16 for task local_to_gcs_task (403 POST https://storage.googleapis.com/upload/storage/v1/b/twitter-etl-bucket/o?uploadType=resumable: {
  "error": {
    "code": 403,
    "message": "690814178061-compute@developer.gserviceaccount.com does not have storage.objects.create access to the Google Cloud Storage object. Permission 'storage.objects.create' denied on resource (or it may not exist).",
    "errors": [
      {
        "message": "690814178061-compute@developer.gserviceaccount.com does not have storage.objects.create access to the Google Cloud Storage object. Permission 'storage.objects.create' denied on resource (or it may not exist).",
        "domain": "global",
        "reason": "forbidden"
      }
    ]
  }
}
: ('Request failed with status code', 403, 'Expected one of', <HTTPStatus.OK: 200>, <HTTPStatus.CREATED: 201>); 415)
[2023-05-22 14:20:45,972] {local_task_job.py:156} INFO - Task exited with return code 1
[2023-05-22 14:20:46,007] {local_task_job.py:273} INFO - 0 downstream tasks scheduled from follow-on schedule check
