[2023-05-26 13:06:49,924] {taskinstance.py:1159} INFO - Dependencies all met for <TaskInstance: data_ingestion_gcs_dag.bigquery_external_table_task manual__2023-05-26T13:01:40.823457+00:00 [queued]>
[2023-05-26 13:06:49,938] {taskinstance.py:1159} INFO - Dependencies all met for <TaskInstance: data_ingestion_gcs_dag.bigquery_external_table_task manual__2023-05-26T13:01:40.823457+00:00 [queued]>
[2023-05-26 13:06:49,940] {taskinstance.py:1356} INFO - 
--------------------------------------------------------------------------------
[2023-05-26 13:06:49,942] {taskinstance.py:1357} INFO - Starting attempt 2 of 2
[2023-05-26 13:06:49,943] {taskinstance.py:1358} INFO - 
--------------------------------------------------------------------------------
[2023-05-26 13:06:49,961] {taskinstance.py:1377} INFO - Executing <Task(BigQueryCreateExternalTableOperator): bigquery_external_table_task> on 2023-05-26 13:01:40.823457+00:00
[2023-05-26 13:06:49,968] {standard_task_runner.py:52} INFO - Started process 1384 to run task
[2023-05-26 13:06:49,972] {standard_task_runner.py:79} INFO - Running: ['***', 'tasks', 'run', 'data_ingestion_gcs_dag', 'bigquery_external_table_task', 'manual__2023-05-26T13:01:40.823457+00:00', '--job-id', '72', '--raw', '--subdir', 'DAGS_FOLDER/data_ingestion_gcs.py', '--cfg-path', '/tmp/tmpqugcgxhx', '--error-file', '/tmp/tmp7g2s5phn']
[2023-05-26 13:06:49,975] {standard_task_runner.py:80} INFO - Job 72: Subtask bigquery_external_table_task
[2023-05-26 13:06:50,047] {task_command.py:370} INFO - Running <TaskInstance: data_ingestion_gcs_dag.bigquery_external_table_task manual__2023-05-26T13:01:40.823457+00:00 [running]> on host ca6ba07bb7b3
[2023-05-26 13:06:50,109] {logging_mixin.py:115} WARNING - /home/***/.local/lib/python3.7/site-packages/***/utils/context.py:202 AirflowContextDeprecationWarning: Accessing 'execution_date' from the template is deprecated and will be removed in a future version. Please use 'data_interval_start' or 'logical_date' instead.
[2023-05-26 13:06:50,165] {taskinstance.py:1571} INFO - Exporting the following env vars:
AIRFLOW_CTX_DAG_OWNER=***
AIRFLOW_CTX_DAG_ID=data_ingestion_gcs_dag
AIRFLOW_CTX_TASK_ID=bigquery_external_table_task
AIRFLOW_CTX_EXECUTION_DATE=2023-05-26T13:01:40.823457+00:00
AIRFLOW_CTX_TRY_NUMBER=2
AIRFLOW_CTX_DAG_RUN_ID=manual__2023-05-26T13:01:40.823457+00:00
[2023-05-26 13:06:50,171] {crypto.py:82} WARNING - empty cryptography key - values will not be stored encrypted.
[2023-05-26 13:06:50,173] {base.py:68} INFO - Using connection ID 'google_cloud_default' for task execution.
[2023-05-26 13:06:50,623] {taskinstance.py:1889} ERROR - Task failed with exception
Traceback (most recent call last):
  File "/home/airflow/.local/lib/python3.7/site-packages/airflow/providers/google/cloud/operators/bigquery.py", line 1108, in execute
    table_resource=self.table_resource,
  File "/home/airflow/.local/lib/python3.7/site-packages/airflow/providers/google/common/hooks/base_google.py", line 439, in inner_wrapper
    return func(self, *args, **kwargs)
  File "/home/airflow/.local/lib/python3.7/site-packages/airflow/providers/google/cloud/hooks/bigquery.py", line 400, in create_empty_table
    table=table, exists_ok=exists_ok, retry=retry
  File "/home/airflow/.local/lib/python3.7/site-packages/google/cloud/bigquery/client.py", line 755, in create_table
    timeout=timeout,
  File "/home/airflow/.local/lib/python3.7/site-packages/google/cloud/bigquery/client.py", line 782, in _call_api
    return call()
  File "/home/airflow/.local/lib/python3.7/site-packages/google/api_core/retry.py", line 288, in retry_wrapped_func
    on_error=on_error,
  File "/home/airflow/.local/lib/python3.7/site-packages/google/api_core/retry.py", line 190, in retry_target
    return target()
  File "/home/airflow/.local/lib/python3.7/site-packages/google/cloud/_http/__init__.py", line 494, in api_request
    raise exceptions.from_http_response(response)
google.api_core.exceptions.BadRequest: 400 POST https://bigquery.googleapis.com/bigquery/v2/projects/twitter-etl-385111/datasets/trips_data_all/tables?prettyPrint=false: Error while reading table: external_table, error message: Input file is not in Parquet format. File: gs://twitter-etl-bucket/raw/yellow_tripdata_2023-05.parquet
[2023-05-26 13:06:50,642] {taskinstance.py:1400} INFO - Marking task as FAILED. dag_id=data_ingestion_gcs_dag, task_id=bigquery_external_table_task, execution_date=20230526T130140, start_date=20230526T130649, end_date=20230526T130650
[2023-05-26 13:06:50,654] {standard_task_runner.py:97} ERROR - Failed to execute job 72 for task bigquery_external_table_task (400 POST https://bigquery.googleapis.com/bigquery/v2/projects/twitter-etl-385111/datasets/trips_data_all/tables?prettyPrint=false: Error while reading table: external_table, error message: Input file is not in Parquet format. File: gs://twitter-etl-bucket/raw/yellow_tripdata_2023-05.parquet; 1384)
[2023-05-26 13:06:50,669] {local_task_job.py:156} INFO - Task exited with return code 1
[2023-05-26 13:06:50,711] {local_task_job.py:273} INFO - 0 downstream tasks scheduled from follow-on schedule check
